<?xml version="1.0"?>
<!-- This sdf file is based on schunk_wsg_50.sdf -->
<sdf version="1.7">
  <model name="Schunk_Gripper">
    <link name="body">
      <pose>0 -0.049133 0 0 0 0</pose>
      <inertial>
        <mass>0.988882</mass>
        <inertia>
          <ixx>0.162992</ixx>
          <ixy>0</ixy>
          <ixz>0</ixz>
          <iyy>0.162992</iyy>
          <iyz>0</iyz>
          <izz>0.164814</izz>
        </inertia>
      </inertial>
      <self_collide>0</self_collide>
      <kinematic>0</kinematic>
      <visual name="visual">
        <geometry>
          <mesh>
            <scale>1 1 1</scale>
            <uri>../meshes/wsg_body.obj</uri>
          </mesh>
        </geometry>
        <material>
          <diffuse>0.7 0.7 0.7 1</diffuse>
        </material>
      </visual>
      <collision name="collision">
        <laser_retro>0</laser_retro>
        <max_contacts>10</max_contacts>
        <geometry>
          <box>
            <size>0.146 0.0725 0.05</size>
          </box>
        </geometry>
        <drake:proximity_properties>
            <drake:mesh_resolution_hint>0.01</drake:mesh_resolution_hint>
            <drake:elastic_modulus>0.5e9</drake:elastic_modulus>
            <drake:hunt_crossley_dissipation>4.5</drake:hunt_crossley_dissipation>
            <drake:mu_dynamic>1.0</drake:mu_dynamic>
            <drake:mu_static>1.0</drake:mu_static>
            <drake:soft_hydroelastic/>
        </drake:proximity_properties>
      </collision>
    </link>
    <frame name="body_frame">
      <pose relative_to="body"/>
    </frame>
    <link name="left_finger">
      <pose>-0.006 0.028 0 0 3.141592 0</pose>
      <inertial>
        <mass>0.05</mass>
        <inertia>
          <ixx>0.16</ixx>
          <ixy>0</ixy>
          <ixz>0</ixz>
          <iyy>0.16</iyy>
          <iyz>0</iyz>
          <izz>0.16</izz>
        </inertia>
      </inertial>
      <self_collide>0</self_collide>
      <kinematic>0</kinematic>
      <visual name="visual">
        <geometry>
          <mesh>
            <scale>1 1 1</scale>
            <uri>../meshes/finger_without_tip.obj</uri>
          </mesh>
        </geometry>
        <material>
          <diffuse>0.2 0.2 0.2 1</diffuse>
        </material>
      </visual>
      <collision name="collision">
        <laser_retro>0</laser_retro>
        <max_contacts>10</max_contacts>
        <geometry>
          <box>
            <size>0.012 0.082 0.02</size>
          </box>
        </geometry>
        <drake:proximity_properties>
            <drake:mesh_resolution_hint>0.01</drake:mesh_resolution_hint>
            <drake:elastic_modulus>0.5e9</drake:elastic_modulus>
            <drake:hunt_crossley_dissipation>4.5</drake:hunt_crossley_dissipation>
            <drake:mu_dynamic>1.0</drake:mu_dynamic>
            <drake:mu_static>1.0</drake:mu_static>
            <drake:soft_hydroelastic/>
        </drake:proximity_properties>
      </collision>
    </link>
    <link name="right_finger">
      <pose>0.006 0.028 0 0 0 0</pose>
      <inertial>
        <mass>0.05</mass>
        <inertia>
          <ixx>0.16</ixx>
          <ixy>0</ixy>
          <ixz>0</ixz>
          <iyy>0.16</iyy>
          <iyz>0</iyz>
          <izz>0.16</izz>
        </inertia>
      </inertial>
      <self_collide>0</self_collide>
      <kinematic>0</kinematic>
      <visual name="visual">
        <geometry>
          <mesh>
            <scale>1 1 1</scale>
            <uri>../meshes/finger_without_tip.obj</uri>
          </mesh>
        </geometry>
        <material>
          <diffuse>0.2 0.2 0.2 1</diffuse>
        </material>
      </visual>
      <collision name="collision">
        <laser_retro>0</laser_retro>
        <max_contacts>10</max_contacts>
        <geometry>
          <box>
            <size>0.012 0.082 0.02</size>
          </box>
        </geometry>
        <drake:proximity_properties>
            <drake:mesh_resolution_hint>0.01</drake:mesh_resolution_hint>
            <drake:elastic_modulus>0.5e9</drake:elastic_modulus>
            <drake:hunt_crossley_dissipation>4.5</drake:hunt_crossley_dissipation>
            <drake:mu_dynamic>1.0</drake:mu_dynamic>
            <drake:mu_static>1.0</drake:mu_static>
            <drake:soft_hydroelastic/>
        </drake:proximity_properties>
      </collision>
    </link>
    <joint name="left_finger_sliding_joint" type="prismatic">
      <parent>body</parent>
      <child>left_finger</child>
      <axis>
        <xyz>-1 0 0</xyz>
        <!-- Drake attaches an actuator to all and only joints with a nonzero
             effort limit. -->
        <limit>
          <lower>-0.055</lower>
          <upper>0</upper>
          <effort>80</effort>
          <stiffness>15000</stiffness>
          <dissipation>50</dissipation>
        </limit>
        <dynamics>
          <spring_reference>0</spring_reference>
          <spring_stiffness>0</spring_stiffness>
          <damping>0</damping>
          <friction>0</friction>
        </dynamics>
      </axis>
      <physics>
        <ode>
          <limit>
            <cfm>0</cfm>
            <erp>0.2</erp>
          </limit>
          <suspension>
            <cfm>0</cfm>
            <erp>0.2</erp>
          </suspension>
        </ode>
      </physics>
    </joint>
    <joint name="right_finger_sliding_joint" type="prismatic">
      <parent>body</parent>
      <child>right_finger</child>
      <axis>
        <xyz>1 0 0</xyz>
        <!-- Drake attaches an actuator to all and only joints with a nonzero
             effort limit. -->
        <limit>
          <lower>0</lower>
          <upper>0.055</upper>
          <effort>80</effort>
          <stiffness>15000</stiffness>
          <dissipation>50</dissipation>
        </limit>
        <dynamics>
          <spring_reference>0</spring_reference>
          <spring_stiffness>0</spring_stiffness>
          <damping>0</damping>
          <friction>0</friction>
        </dynamics>
      </axis>
      <physics>
        <ode>
          <limit>
            <cfm>0</cfm>
            <erp>0.2</erp>
          </limit>
          <suspension>
            <cfm>0</cfm>
            <erp>0.2</erp>
          </suspension>
        </ode>
      </physics>
    </joint>
    <static>0</static>
    <allow_auto_disable>1</allow_auto_disable>
  </model>
</sdf>
